<mujoco model="UR3e">
    <compiler angle="radian" meshdir="."/>
    <size njmax="500" nconmax="100" />
    <asset>
        <mesh name="base" file="meshes/base.stl" />
        <mesh name="shoulder" file="meshes/shoulder.stl" />
        <mesh name="upperarm" file="meshes/upperarm.stl" />
        <mesh name="forearm" file="meshes/forearm.stl" />
        <mesh name="wrist1" file="meshes/wrist1.stl" />
        <mesh name="wrist2" file="meshes/wrist2.stl" />
        <mesh name="wrist3" file="meshes/wrist3.stl" />
        <!-- <mesh name="gripper_base_link" file="meshes/v2_realistic/base_link.STL" />
        <mesh name="left_short_link" file="meshes/v2_realistic/left_short_link.STL" />
        <mesh name="left_gripper_finger" file="meshes/v2_realistic/left_gripper_finger.STL" /> 
        <mesh name="left_torque_transfer" file="meshes/v2_realistic/left_torque_transfer.STL" />
        <mesh name="left_long_link" file="meshes/v2_realistic/left_long_link.STL" />
        <mesh name="right_short_link" file="meshes/v2_realistic/right_short_link.STL" />
        <mesh name="right_gripper_finger" file="meshes/v2_realistic/right_gripper_finger.STL" />
        <mesh name="right_torque_transfer" file="meshes/v2_realistic/right_torque_transfer.STL" />
        <mesh name="right_long_link" file="meshes/v2_realistic/right_long_link.STL" /> -->
    </asset>

    <actuator>
        <motor ctrllimited="true" ctrlrange="-180 150" joint="joint_1" name="torq_1"/>
        <motor ctrllimited="true" ctrlrange="-180 150" joint="joint_2" name="torq_2"/>
        <motor ctrllimited="true" ctrlrange="-180 150" joint="joint_3" name="torq_3"/>
        <motor ctrllimited="true" ctrlrange="-180 150" joint="joint_4" name="torq_4"/>
        <motor ctrllimited="true" ctrlrange="-180 150" joint="joint_5" name="torq_5"/>
        <motor ctrllimited="true" ctrlrange="-180 150" joint="joint_6" name="torq_6"/>
        <!-- <position ctrllimited="true" ctrlrange="-0.74 0.74" joint="base_left_short_joint" kp="15" name="left_finger_joint" forcelimited="true" forcerange="-5 5"/>
        <position ctrllimited="true" ctrlrange="-0.74 0.74" joint="base_right_short_joint" kp="15" name="right_finger_joint" forcelimited="true" forcerange="-5 5"/>
        <position ctrllimited="true" ctrlrange="-0.0001 0.0001" joint="base_left_torque_joint" kp="2" name="left_torque_joint" forcelimited="true" forcerange="-2 2"/>
        <position ctrllimited="true" ctrlrange="-0.0001 0.0001" joint="base_right_torque_joint" kp="2" name="right_torque_joint" forcelimited="true" forcerange="-2 2"/> -->
    </actuator>

    <!-- <equality>
        <connect body1="left_long_link" body2="left_gripper_finger" active="true" solref='0.005 1' anchor="-0.0 -0.003 0.039"/>
        <connect body1="right_long_link" body2="right_gripper_finger" active="true" solref='0.005 1' anchor="0.0 0.005 0.039"/>
    </equality> -->



    <worldbody>
        <!-- <geom quat="-1 0 0 0" type="mesh" group="1"  rgba="0.7 0.7 0.7 1" mesh="base" />
        <geom quat="-1 0 0 0" type="mesh" group="0"  rgba="0.7 0.7 0.7 1" mesh="base" /> -->
        <body name="shoulder_link" pos="0 0 0.15185" quat="0 0 0 1">
            <inertial pos="0 0 0" mass="2" diaginertia="0.00809316 0.00809316 0.005625" />
            <joint name="joint_1" pos="0 0 0" axis="0 0 1" limited="true" range="-6.28319 6.28319" />
            <geom quat="0 0 0 1" type="mesh" rgba="0.7 0.7 0.7 1" group="1"  mesh="shoulder" />
            <geom quat="0 0 0 1" type="mesh" rgba="0.7 0.7 0.7 1" group="0"  mesh="shoulder" />
            <body name="upper_arm_link" pos="0 0 0" quat="0.707107 0.707107 0 0">
                <inertial pos="-0.121825 0 0.12" quat="0.707107 0 0.707107 0" mass="3.42" diaginertia="0.0217285 0.0217285 0.00961875" />
                <joint name="joint_2" pos="0 0 0" axis="0 0 1" limited="true" range="-6.28319 6.28319" />
                <geom pos="0 0 0.12" quat="0.5 0.5 -0.5 -0.5" group="1"  type="mesh" rgba="0.7 0.7 0.7 1" mesh="upperarm" />
                <geom pos="0 0 0.12" quat="0.5 0.5 -0.5 -0.5" group="0"  type="mesh" rgba="0.7 0.7 0.7 1" mesh="upperarm" />
                <body name="forearm_link" pos="-0.24355 0 0">
                    <inertial pos="-0.1066 0 0.027" quat="0.707107 0 0.707107 0" mass="1.26" diaginertia="0.00654457 0.00654457 0.00354375" />
                    <joint name="joint_3" pos="0 0 0" axis="0 0 1" limited="true" range="-3.14159 3.14159" />
                    <geom pos="0 0 0.027" quat="0.5 0.5 -0.5 -0.5" group="1"  type="mesh" rgba="0.7 0.7 0.7 1" mesh="forearm" />
                    <geom pos="0 0 0.027" quat="0.5 0.5 -0.5 -0.5" group="0"  type="mesh" rgba="0.7 0.7 0.7 1" mesh="forearm" />
                    <body name="wrist_1_link" pos="-0.2132 0 0.13105">
                        <inertial pos="0 0 0" quat="0.5 0.5 -0.5 0.5" mass="0.8" diaginertia="0.00225 0.002085 0.002085" />
                        <joint name="joint_4" pos="0 0 0" axis="0 0 1" limited="true" range="-6.28319 6.28319" />
                        <geom pos="0 0 -0.104" quat="0.707107 0.707107 0 0" group="1"  type="mesh" rgba="0.7 0.7 0.7 1" mesh="wrist1" />
                        <geom pos="0 0 -0.104" quat="0.707107 0.707107 0 0" group="0"  type="mesh" rgba="0.7 0.7 0.7 1" mesh="wrist1" />
                        <body name="wrist_2_link" pos="0 -0.08535 -1.75056e-11" quat="0.707107 0.707107 0 0">
                            <inertial pos="0 0 0" quat="0.5 0.5 -0.5 0.5" mass="0.8" diaginertia="0.00225 0.002085 0.002085" />
                            <joint name="joint_5" pos="0 0 0"  axis="0 0 1" limited="true" range="-6.28319 6.28319" />
                            <geom pos="0 0 -0.08535" type="mesh" group="1" rgba="0.7 0.7 0.7 1" mesh="wrist2" />
                            <geom pos="0 0 -0.08535" type="mesh" group="0" rgba="0.7 0.7 0.7 1" mesh="wrist2" />
                            <body name="wrist_3_link" pos="0 0.0921 -1.889e-11" quat="0.707107 -0.707107 0 0">
                                <inertial pos="0 0 -0.02" quat="0.5 0.5 -0.5 0.5" mass="0.35" diaginertia="0.0001792 0.000136267 0.000136267" />
                                <joint name="joint_6" pos="0 0 0" axis="0 0 1" limited="true" range="-6.28319 6.28319" />
                                <geom pos="0 0 -0.0921" quat="0.707107 0.707107 0 0" group="1" type="mesh" rgba="0.7 0.7 0.7 1" mesh="wrist3" />
                                <geom pos="0 0 -0.0921" quat="0.707107 0.707107 0 0" group="0" type="mesh" rgba="0.7 0.7 0.7 1" mesh="wrist3" />
                                
                            <body name="right_hand" pos="0 0 0.09" quat="0 0 0 1" >
                                        <!-- This sites were added for visualization. They are all standardized between models-->
                                        <!-- Position mimics the gripper attachment point (right_hand) -->
                                        <!--  Y-axis should be perpendicular to grasping motion, and Z-axis should point out of the robot eef -->
                                        <site name="ee" pos="0 0 0" size="0.01 0.01 0.01" rgba="0 0 1 1" type="sphere" group="1"/>
                                        <site name="ee_x" pos="0 0 0" size="0.005 .1"  quat="0.707105 0.707108 0 0 " rgba="1 0 0 0" type="cylinder" group="1"/>
                                        <site name="ee_z" pos="0 0 0" size="0.005 .1" quat="0.707105 0 0 0.707108" rgba="0 0 1 0" type="cylinder" group="1"/>
                                        <site name="ee_y" pos="0 0 0" size="0.005 .1" quat="0.707105 0 0.707108 0 " rgba="0 1 0 0" type="cylinder" group="1"/>
                                        <!-- This camera points out from the eef. -->
                                        <camera mode="fixed" name="eye_in_hand" pos="0.05 0 0" quat="0 0.707108 0.707108 0" fovy="75"/>
                                        <!-- To add gripper -->
                                    </body>

                            
                            
                            
                            
                            </body>
                        </body>
                    </body>
                </body>
            </body>
        </body>
    </worldbody>

</mujoco>
