<mujoco model="iPhone12ProMax">
  <asset>
    <mesh file="meshes/iPhone 12 Pro Max.stl" name="iPhone12ProMax_mesh"/>
    <texture file="../textures/black_sq.png" name="tex-iPhone"/> 
    <material name="iPhone_back" reflectance="0.7" texrepeat="1 1" texture="tex-iPhone" texuniform="true"/> 
  </asset>
  <worldbody>
    <body>
      <body name="object">
        <joint name="iPhone12_joint" pos="0 0 0" type="slide" axis="1 1 0" damping="1"/> 
        <geom pos="0.59 0 0.745" mesh="iPhone12ProMax_mesh" type="mesh" material="iPhone_back" rgba="0.8 0.8 0.8 0.3" size="0.001 0.001 0.001" conaffinity="1" contype="1" group="1" mass="0.228"/>
        <geom pos="0.59 0 0.745" mesh="iPhone12ProMax_mesh" type="mesh" group="0" rgba="0.8 0.8 0.8 0.3"/>        
      </body>      
    </body>
  </worldbody>
</mujoco>
