<mujoco model="panda_hand">
    <asset>
        <mesh name="hand" file="meshes/panda_gripper/hand.stl" />
        <!-- <mesh name="hand_vis" file="meshes/panda_gripper/hand_vis.stl" /> -->
        <mesh name="hand_vis" file="meshes/D3_gripper_v9/base_link.STL" />
        <mesh name="finger" file="meshes/panda_gripper/finger.stl" />
        <mesh name="finger_vis" file="meshes/panda_gripper/finger_vis.stl" />
        <mesh name="finger_vis2" file="meshes/panda_gripper/finger_longer.stl" />
        <mesh name="left_gripper_finger" file="meshes/D3_gripper_v9/left_gripper_finger.STL" />
        <mesh name="right_gripper_finger" file="meshes/D3_gripper_v9/right_gripper_finger.STL" />
    </asset>
    <actuator>
        <position ctrllimited="true" ctrlrange="0.0 0.04" joint="finger_joint1" kp="1000" name="gripper_finger_joint1" forcelimited="true" forcerange="-20 20"/>
        <position ctrllimited="true" ctrlrange="-0.04 0.0" joint="finger_joint2" kp="1000" name="gripper_finger_joint2" forcelimited="true" forcerange="-20 20"/>
    </actuator>
    <worldbody>
        <body name="right_gripper" pos="0 0 -0.09" quat="0.707107 0 0 1">
            <site name="ft_frame" pos="0 0 0" size="0.01 0.01 0.01" rgba="1 0 0 1" type="sphere" group="1"/>
            <inertial pos="0 0 0.17" quat="0.707107 0.707107 0 0" mass="0.3" diaginertia="0.09 0.07 0.05" />
            <geom pos="0 0 0" quat="0.707107 0 0 0.707107" type="mesh" contype="0" conaffinity="0" group="1" mesh="hand_vis" name="hand_visual" rgba="1 1 1 1" />
           <!--  <geom pos="0 0 0." quat="0.707107 0 0 0.707107" type="mesh" mesh="hand"  group="0" name="hand_collision"/> -->
            <!-- This site was added for visualization. -->
            <site name="grip_site" pos="0 0 0.125" size="0.01 0.01 0.01" rgba="1 0 0 0.5" type="sphere" group="1"/>
            <!-- This site was added for visualization. -->
            <site name="grip_site_cylinder" pos="0 0 0.1399" size="0.005 10" rgba="0 1 0 0.3" type="cylinder" group="1"/>

            <body name="leftfinger" pos="0 0 0.0524" quat="0.707107 0 0 0.707107">
                <inertial pos="0 0 0.05" mass="0.1" diaginertia="0.01 0.01 0.005" />
                <joint name="finger_joint1" pos="0 0 0" axis="0 1 0" type="slide" limited="true" range="0.0 0.04" damping="100" armature="1.0" frictionloss="1.0"/>
                <!-- <geom type="mesh" contype="0" conaffinity="0" group="1" mesh="finger_vis" name="finger1_visual" rgba="0.499 0.499 0.499 1" /> -->
                <!-- <geom type="mesh" group="0" conaffinity="1" contype="0" solref="0.02 1" friction="1 0.005 0.0001" condim="4" mesh="finger" name="finger1_collision"/> -->
                <body name="finger_joint1_tip" pos="0 0.0085 0.056">
                    <inertial pos="0 0 0" quat="0 0 0 1" mass="0.01" diaginertia="0.01 0.01 0.01" />
                    <!-- <geom size="0.008 0.004 0.008" pos="0 -0.005 -0.015" quat="0 0 0 1" type="box" group="0" solref="0.01 0.5" friction = "2 0.05 0.0001" conaffinity="1" contype="1" name="finger1_pad_collision"/> -->
                </body>
                <body name="right_gripper_finger" pos="0 0.039 0.0608">
                <inertial pos="-0.0018228 0.023251 -0.0083165" quat="0.537087 0.457285 0.441346 0.554654" mass="0.032218" diaginertia="1.84182e-05 1.82648e-05 6.97848e-07" />
                <!-- <joint name="right_short_gripper_joint" pos="0 0 0" axis="0 1 0" /> -->
                <geom type="mesh" group="1" contype="0" conaffinity="0" rgba="0.79216 0.81961 0.93333 1" mesh="right_gripper_finger" />
                 <geom type="mesh" group="0" rgba="0.79216 0.81961 0.93333 1" mesh="right_gripper_finger" />
                 <body name="finger_R1" pos="0.0938 -0.03058 0.01291">
                    <inertial pos="0 0 0" quat="0 0 0 1" mass="0.01" diaginertia="0.01 0.01 0.01" />
                    <geom size="0.00627 0.006 0.00601" pos="0 0 0" quat="0 0 0 1" type="box" group="0" solref="0.01 0.5" friction = "2 0.05 0.0001" conaffinity="1" contype="1" name="finger_R1_pad"/>
                </body>
                <body name="finger_R1_top" pos="0.0938 -0.03864 0.0184">
                    <inertial pos="0 0 0" quat="0 0 0 1" mass="0.01" diaginertia="0.01 0.01 0.01" />
                    <geom size="0.006 0.00175 0.00049" pos="0 0 0" quat="0 0 0 1" type="box" group="0" solref="0.01 0.5" friction = "2 0.05 0.0001" conaffinity="1" contype="1" name="finger_R1_pad_top"/>
                </body>
                <body name="finger_R1_bot" pos="0.0938 -0.03864 0.00736">
                    <inertial pos="0 0 0" quat="0 0 0 1" mass="0.01" diaginertia="0.01 0.01 0.01" />
                    <geom size="0.006 0.00175 0.00049" pos="0 0 0" quat="0 0 0 1" type="box" group="0" solref="0.01 0.5" friction = "2 0.05 0.0001" conaffinity="1" contype="1" name="finger_R1_pad_bot"/>
                </body>
                <body name="finger_R2" pos="0.03199 -0.03058 0.01291">
                    <inertial pos="0 0 0" quat="0 0 0 1" mass="0.01" diaginertia="0.01 0.01 0.01" />
                    <geom size="0.00627 0.006 0.00601" pos="0 0 0" quat="0 0 0 1" type="box" group="0" solref="0.01 0.5" friction = "2 0.05 0.0001" conaffinity="1" contype="1" name="finger_R2_pad"/>
                </body>
                <body name="finger_R2_top" pos="0.03199 -0.03864 0.0184">
                    <inertial pos="0 0 0" quat="0 0 0 1" mass="0.01" diaginertia="0.01 0.01 0.01" />
                    <geom size="0.006 0.00175 0.00049" pos="0 0 0" quat="0 0 0 1" type="box" group="0" solref="0.01 0.5" friction = "2 0.05 0.0001" conaffinity="1" contype="1" name="finger_R2_pad_top"/>
                </body>
                <body name="finger_R2_bot" pos="0.03199 -0.03864 0.00736">
                    <inertial pos="0 0 0" quat="0 0 0 1" mass="0.01" diaginertia="0.01 0.01 0.01" />
                    <geom size="0.006 0.00175 0.00049" pos="0 0 0" quat="0 0 0 1" type="box" group="0" solref="0.01 0.5" friction = "2 0.05 0.0001" conaffinity="1" contype="1" name="finger_R2_pad_bot"/>
                </body>
                <body name="finger_R3" pos="0 -0.03058 0.01291">
                    <inertial pos="0 0 0" quat="0 0 0 1" mass="0.01" diaginertia="0.01 0.01 0.01" />
                    <geom size="0.00627 0.006 0.00601" pos="0 0 0" quat="0 0 0 1" type="box" group="0" solref="0.01 0.5" friction = "2 0.05 0.0001" conaffinity="1" contype="1" name="finger_R3_pad"/>
                </body>
                <body name="finger_R3_top" pos="0 -0.03864 0.0184">
                    <inertial pos="0 0 0" quat="0 0 0 1" mass="0.01" diaginertia="0.01 0.01 0.01" />
                    <geom size="0.006 0.00175 0.00049" pos="0 0 0" quat="0 0 0 1" type="box" group="0" solref="0.01 0.5" friction = "2 0.05 0.0001" conaffinity="1" contype="1" name="finger_R3_pad_top"/>
                </body>
                <body name="finger_R3_bot" pos="0 -0.03864 0.00736">
                    <inertial pos="0 0 0" quat="0 0 0 1" mass="0.01" diaginertia="0.01 0.01 0.01" />
                    <geom size="0.006 0.00175 0.00049" pos="0 0 0" quat="0 0 0 1" type="box" group="0" solref="0.01 0.5" friction = "2 0.05 0.0001" conaffinity="1" contype="1" name="finger_R3_pad_bot"/>
                </body>
                <body name="finger_R4" pos="-0.03243 -0.03058 0.01291">
                    <inertial pos="0 0 0" quat="0 0 0 1" mass="0.01" diaginertia="0.01 0.01 0.01" />
                    <geom size="0.00627 0.006 0.00601" pos="0 0 0" quat="0 0 0 1" type="box" group="0" solref="0.01 0.5" friction = "2 0.05 0.0001" conaffinity="1" contype="1" name="finger_R4_pad"/>
                </body>
                <body name="finger_R4_top" pos="-0.03243 -0.03864 0.0184">
                    <inertial pos="0 0 0" quat="0 0 0 1" mass="0.01" diaginertia="0.01 0.01 0.01" />
                    <geom size="0.006 0.00175 0.00049" pos="0 0 0" quat="0 0 0 1" type="box" group="0" solref="0.01 0.5" friction = "2 0.05 0.0001" conaffinity="1" contype="1" name="finger_R4_pad_top"/>
                </body>
                <body name="finger_R4_bot" pos="-0.03243 -0.03864 0.00736">
                    <inertial pos="0 0 0" quat="0 0 0 1" mass="0.01" diaginertia="0.01 0.01 0.01" />
                    <geom size="0.006 0.00175 0.00049" pos="0 0 0" quat="0 0 0 1" type="box" group="0" solref="0.01 0.5" friction = "2 0.05 0.0001" conaffinity="1" contype="1" name="finger_R4_pad_bot"/>
                </body>
             </body>
                
               
            </body>
            <body name="rightfinger" pos="0 0 0.0524" quat="0.707107 0 0 0.707107">
                <inertial pos="0 0 0.05" mass="0.1" diaginertia="0.01 0.01 0.005" />
                <joint name="finger_joint2" pos="0 0 0" axis="0 1 0" type="slide" limited="true" range="-0.04 0.0" damping="100" armature="1.0" frictionloss="1.0"/>
                <!-- <geom quat="0 0 0 1" type="mesh" contype="0" conaffinity="0" group="1" mesh="finger_vis" name="finger2_visual" rgba="0.499 0.499 0.499 1" /> -->
                <!-- <geom quat="0 0 0 1" type="mesh" group="0" conaffinity="1" contype="0" solref="0.02 1" friction="1 0.005 0.0001" condim="4" mesh="finger" name="finger2_collision"/> -->
                <body name="finger_joint2_tip" pos="0 -0.0085 0.056">
                    <inertial pos="0 0 0" quat="0 0 0 1" mass="0.01" diaginertia="0.01 0.01 0.01" />
                    <!-- <geom size="0.008 0.004 0.008" pos="0 0.005 -0.015" quat="0 0 0 1" type="box" group="0" solref="0.01 0.5" friction = "2 0.05 0.0001" conaffinity="1" contype="1" name="finger2_pad_collision"/> -->
                </body>
                <body name="left_gripper_finger" pos="0 -0.039 0.059" quat="-0.707107 0 0 0">
                <inertial pos="0.0018228 -0.00018314 -0.0083165" quat="0.457285 0.537087 0.554654 0.441346" mass="0.032218" diaginertia="1.84182e-05 1.82648e-05 6.97848e-07" />
                <!-- <joint name="left_short_gripper_joint" pos="0 0 0" axis="0 1 0" /> -->
                <geom type="mesh" group="1" contype="0" conaffinity="0" rgba="0.79216 0.81961 0.93333 1" mesh="left_gripper_finger" />
                <geom type="mesh" group="0" rgba="0.79216 0.81961 0.93333 1" mesh="left_gripper_finger" />
                <body name="finger_L1" pos="0.0938 0.03058 0.01431">
                    <inertial pos="0 0 0" quat="0 0 0 1" mass="0.01" diaginertia="0.01 0.01 0.01" />
                    <geom size="0.00627 0.006 0.00601" pos="0 0 0" quat="0 0 0 1" type="box" group="0" solref="0.01 0.5" friction = "2 0.05 0.0001" conaffinity="1" contype="1" name="finger_L1_pad"/>
                </body>
                <body name="finger_L1_top" pos="0.0938 0.03864 0.0198">
                    <inertial pos="0 0 0" quat="0 0 0 1" mass="0.01" diaginertia="0.01 0.01 0.01" />
                    <geom size="0.006 0.00175 0.00049" pos="0 0 0" quat="0 0 0 1" type="box" group="0" solref="0.01 0.5" friction = "2 0.05 0.0001" conaffinity="1" contype="1" name="finger_L1_pad_top"/>
                </body>
                <body name="finger_L1_bot" pos="0.0938 0.03864 0.00876">
                    <inertial pos="0 0 0" quat="0 0 0 1" mass="0.01" diaginertia="0.01 0.01 0.01" />
                    <geom size="0.006 0.00175 0.00049" pos="0 0 0" quat="0 0 0 1" type="box" group="0" solref="0.01 0.5" friction = "2 0.05 0.0001" conaffinity="1" contype="1" name="finger_L1_pad_bot"/>
                </body>
                <body name="finger_L2" pos="0.02026 0.03058 0.01431">
                    <inertial pos="0 0 0" quat="0 0 0 1" mass="0.01" diaginertia="0.01 0.01 0.01" />
                    <geom size="0.006 0.00627 0.00601" pos="0 0 0" quat="0 0 0 1" type="box" group="0" solref="0.01 0.5" friction = "2 0.05 0.0001" conaffinity="1" contype="1" name="finger_L2_pad"/>
                </body>
                <body name="finger_L2_top" pos="0.02026 0.03864 0.0198">
                    <inertial pos="0 0 0" quat="0 0 0 1" mass="0.01" diaginertia="0.01 0.01 0.01" />
                    <geom size="0.006 0.00175 0.00049" pos="0 0 0" quat="0 0 0 1" type="box" group="0" solref="0.01 0.5" friction = "2 0.05 0.0001" conaffinity="1" contype="1" name="finger_L2_pad_top"/>
                </body>
                <body name="finger_L2_bot" pos="0.02026 0.03864 0.00876">
                    <inertial pos="0 0 0" quat="0 0 0 1" mass="0.01" diaginertia="0.01 0.01 0.01" />
                    <geom size="0.006 0.00175 0.00049" pos="0 0 0" quat="0 0 0 1" type="box" group="0" solref="0.01 0.5" friction = "2 0.05 0.0001" conaffinity="1" contype="1" name="finger_L2_pad_bot"/>
                </body>
                <body name="finger_L3" pos="-0.02026 0.03058 0.01431">
                    <inertial pos="0 0 0" quat="0 0 0 1" mass="0.01" diaginertia="0.01 0.01 0.01" />
                    <geom size="0.006 0.00627 0.00601" pos="0 0 0" quat="0 0 0 1" type="box" group="0" solref="0.01 0.5" friction = "2 0.05 0.0001" conaffinity="1" contype="1" name="finger_L3_pad"/>
                </body>
                <body name="finger_L3_top" pos="-0.02026 0.03864 0.0198">
                    <inertial pos="0 0 0" quat="0 0 0 1" mass="0.01" diaginertia="0.01 0.01 0.01" />
                    <geom size="0.006 0.00175 0.00049" pos="0 0 0" quat="0 0 0 1" type="box" group="0" solref="0.01 0.5" friction = "2 0.05 0.0001" conaffinity="1" contype="1" name="finger_L3_pad_top"/>
                </body>
                <body name="finger_L3_bot" pos="-0.02026 0.03864 0.00876">
                    <inertial pos="0 0 0" quat="0 0 0 1" mass="0.01" diaginertia="0.01 0.01 0.01" />
                    <geom size="0.006 0.00175 0.00049" pos="0 0 0" quat="0 0 0 1" type="box" group="0" solref="0.01 0.5" friction = "2 0.05 0.0001" conaffinity="1" contype="1" name="finger_L3_pad_bot"/>
                </body>
                <body name="finger_L4" pos="-0.0938 0.03058 0.01431">
                    <inertial pos="0 0 0" quat="0 0 0 1" mass="0.01" diaginertia="0.01 0.01 0.01" />
                    <geom size="0.006 0.00627 0.00601" pos="0 0 0" quat="0 0 0 1" type="box" group="0" solref="0.01 0.5" friction = "2 0.05 0.0001" conaffinity="1" contype="1" name="finger_L4_pad"/>
                </body>
                <body name="finger_L4_top" pos="-0.0938 0.03864 0.0198">
                    <inertial pos="0 0 0" quat="0 0 0 1" mass="0.01" diaginertia="0.01 0.01 0.01" />
                    <geom size="0.006 0.00175 0.00049" pos="0 0 0" quat="0 0 0 1" type="box" group="0" solref="0.01 0.5" friction = "2 0.05 0.0001" conaffinity="1" contype="1" name="finger_L4_pad_top"/>
                </body>
                <body name="finger_L4_bot" pos="-0.0938 0.03864 0.00876">
                    <inertial pos="0 0 0" quat="0 0 0 1" mass="0.01" diaginertia="0.01 0.01 0.01" />
                    <geom size="0.006 0.00175 0.00049" pos="0 0 0" quat="0 0 0 1" type="box" group="0" solref="0.01 0.5" friction = "2 0.05 0.0001" conaffinity="1" contype="1" name="finger_L4_pad_bot"/>
                </body>
                </body>

            </body>
        </body>
    </worldbody>
    <sensor>
        <force name="force_ee" site="ft_frame"/>
        <torque name="torque_ee" site="ft_frame"/>
    </sensor>
</mujoco>
